<?xml version="1.0" ?>
<!-- =================================================================================== -->
<!-- |    This document was autogenerated by xacro from base_arm.urdf.xacro            | -->
<!-- |    EDITING THIS FILE BY HAND IS NOT RECOMMENDED                                 | -->
<!-- =================================================================================== -->
<robot name="base_arm" xmlns:body="http://playerstage.sourceforge.net/gazebo/xmlschema/#body" xmlns:controller="http://playerstage.sourceforge.net/gazebo/xmlschema/#controller" xmlns:gazebo="http://playerstage.sourceforge.net/gazebo/xmlschema/#gz" xmlns:geom="http://playerstage.sourceforge.net/gazebo/xmlschema/#geom" xmlns:interface="http://playerstage.sourceforge.net/gazebo/xmlschema/#interface" xmlns:joint="http://playerstage.sourceforge.net/gazebo/xmlschema/#joint" xmlns:model="http://playerstage.sourceforge.net/gazebo/xmlschema/#model" xmlns:physics="http://playerstage.sourceforge.net/gazebo/xmlschema/#physics" xmlns:renderable="http://playerstage.sourceforge.net/gazebo/xmlschema/#renderable" xmlns:rendering="http://playerstage.sourceforge.net/gazebo/xmlschema/#rendering" xmlns:sensor="http://playerstage.sourceforge.net/gazebo/xmlschema/#sensor" xmlns:xi="http://www.w3.org/2001/Xinclude">
  <link name="base_link"/>
  <link name="base_laser_link"/>
  <link name="main">
    <!-- main body -->
    <visual>
      <origin rpy="0 0 0" xyz="0 0 0"/>
      <geometry>
        <cylinder length="0.1" radius="0.2"/>
      </geometry>
      <material name="Cyan">
        <color rgba="0 1.0 1.0 1.0"/>
      </material>
    </visual>
    <!-- upper plate -->
    <visual>
      <origin rpy="0 0 0" xyz="0 0 0.14"/>
      <geometry>
        <cylinder length="0.02" radius="0.18"/>
      </geometry>
      <material name="Cyan">
        <color rgba="0 1.0 1.0 1.0"/>
      </material>
    </visual>
    <!-- poles -->
    <visual>
      <origin rpy="0 0 0" xyz="0.11 0.11 0.09"/>
      <geometry>
        <cylinder length="0.08" radius="0.01"/>
      </geometry>
      <material name="Cyan">
        <color rgba="0 1.0 1.0 1.0"/>
      </material>
    </visual>
    <visual>
      <origin rpy="0 0 0" xyz="-0.11 0.11 0.09"/>
      <geometry>
        <cylinder length="0.08" radius="0.01"/>
      </geometry>
      <material name="Cyan">
        <color rgba="0 1.0 1.0 1.0"/>
      </material>
    </visual>
    <visual>
      <origin rpy="0 0 0" xyz="0.11 -0.11 0.09"/>
      <geometry>
        <cylinder length="0.08" radius="0.01"/>
      </geometry>
      <material name="Cyan">
        <color rgba="0 1.0 1.0 1.0"/>
      </material>
    </visual>
    <visual>
      <origin rpy="0 0 0" xyz="-0.11 -0.11 0.09"/>
      <geometry>
        <cylinder length="0.08" radius="0.01"/>
      </geometry>
      <material name="Cyan">
        <color rgba="0 1.0 1.0 1.0"/>
      </material>
    </visual>
    <!-- marker -->
    <visual>
      <origin rpy="0 0 0" xyz="0.18 0 0.055"/>
      <geometry>
        <cylinder length="0.01" radius="0.02"/>
      </geometry>
      <material name="Green">
        <color rgba="0.0 1.0 0.0 1.0"/>
      </material>
    </visual>
    <!-- collisions -->
    <collision>
      <origin rpy="0 0 0" xyz="0 0 0"/>
      <geometry>
        <cylinder length="0.1" radius="0.2"/>
      </geometry>
    </collision>
    <inertial>
      <mass value="40.0"/>
      <origin rpy="0 0 0" xyz="0 0 0.0"/>
      <inertia ixx="0.4" ixy="0" ixz="0" iyy="0.4" iyz="0" izz="0.64"/>
    </inertial>
  </link>
  <joint name="fixed_base_link_to_main" type="fixed">
    <parent link="base_link"/>
    <child link="main"/>
    <origin rpy="0 0 0" xyz="0.0 0.0 0.05"/>
  </joint>
  <joint name="fixed_main_to_baselaser_link" type="fixed">
    <parent link="main"/>
    <child link="base_laser_link"/>
    <origin rpy="0 0 0" xyz="0.2 0.0 0.15"/>
  </joint>
  <!-- hokuyo -->
  <gazebo reference="base_laser_link">
    <sensor name="head_hokuyo_sensor" type="ray">
      <pose>0 0 0 0 0 0</pose>
      <visualize>false</visualize>
      <update_rate>40</update_rate>
      <ray>
        <scan>
          <horizontal>
            <samples>1000</samples>
            <resolution>1</resolution>
            <min_angle>-2.35619449</min_angle>
            <max_angle>2.35619449</max_angle>
          </horizontal>
        </scan>
        <range>
          <min>0.5</min>
          <max>30.0</max>
          <resolution>0.01</resolution>
        </range>
        <noise>
          <type>gaussian</type>
          <!--
                 Noise parameters based on published spec for Hokuyo laser
                 achieving "+-30mm" accuracy at range < 10m.  A mean of 0.0m and
                 stddev of 0.01m will put 99.7% of samples within 0.03m of the true
                 reading.
                 -->
          <mean>0.0</mean>
          <stddev>0.01</stddev>
        </noise>
      </ray>
      <plugin filename="libgazebo_ros_laser.so" name="gazebo_ros_head_hokuyo_controller">
        <topicName>scan</topicName>
        <frameName>base_laser_link</frameName>
      </plugin>
    </sensor>
  </gazebo>
  <!-- Base control -->
  <gazebo>
    <!--plugin filename="libgazebo_ros_planar_force_move.so" name="cmd_vel_controller"-->
    <plugin filename="libgazebo_ros_planar_move.so" name="cmd_vel_controller">
      <commandTopic>cmd_vel</commandTopic>
      <odometryTopic>odom</odometryTopic>
      <odometryFrame>odom</odometryFrame>
      <odometryRate>40.0</odometryRate>
      <robotBaseFrame>base_link</robotBaseFrame>
      <useForceFeedback>false</useForceFeedback>
      <appliedForceLink>base_link</appliedForceLink>
      <forceGainX>24000</forceGainX>
      <forceGainY>24000</forceGainY>
      <forceGainRot>6000</forceGainRot>
    </plugin>
  </gazebo>
  <link name="anchor_arm_base"/>
  <joint name="make_anchor" type="fixed">
    <parent link="base_link"/>
    <child link="anchor_arm_base"/>
    <origin rpy="0 0 0" xyz="0.0 0.0 0.2"/>
  </joint>
  <link name="arm_base">
    <visual>
      <origin rpy="0.000000000000e+00 -0.000000000000e+00 0.000000000000e+00" xyz="0.000000000000e+00 0.000000000000e+00 1.000000000000e-02"/>
      <geometry>
        <box size="1.000000000000e-01 2.000000000000e-01 2.000000000000e-02"/>
      </geometry>
      <material name="mat__0">
        <color rgba="0 0.7 0.7 1"/>
      </material>
    </visual>
    <visual>
      <origin rpy="-1.608122649677e-16 -0.000000000000e+00 0.000000000000e+00" xyz="0.000000000000e+00 -8.881784197001e-19 2.600000000000e-02"/>
      <geometry>
        <cylinder length="0.0080000000000000002" radius="0.040000000000000001"/>
      </geometry>
      <material name="mat__1">
        <color rgba="0.35 0 0 1"/>
      </material>
    </visual>
    <visual>
      <origin rpy="-1.608122649677e-16 -0.000000000000e+00 0.000000000000e+00" xyz="0.000000000000e+00 3.330669073875e-18 1.500000000000e-02"/>
      <geometry>
        <cylinder length="0.029999999999999999" radius="0.0132"/>
      </geometry>
      <material name="mat__2">
        <color rgba="0 0.7 0 1"/>
      </material>
    </visual>
    <collision>
      <origin rpy="0.000000000000e+00 -0.000000000000e+00 0.000000000000e+00" xyz="0.000000000000e+00 0.000000000000e+00 1.000000000000e-02"/>
      <geometry>
        <box size="1.000000000000e-01 2.000000000000e-01 2.000000000000e-02"/>
      </geometry>
      <material name="mat__3">
        <color rgba="0 0.7 0.7 1"/>
      </material>
    </collision>
    <collision>
      <origin rpy="-1.608122649677e-16 -0.000000000000e+00 0.000000000000e+00" xyz="0.000000000000e+00 -8.881784197001e-19 2.600000000000e-02"/>
      <geometry>
        <cylinder length="0.0080000000000000002" radius="0.040000000000000001"/>
      </geometry>
      <material name="mat__4">
        <color rgba="0.35 0 0 1"/>
      </material>
    </collision>
    <collision>
      <origin rpy="-1.608122649677e-16 -0.000000000000e+00 0.000000000000e+00" xyz="0.000000000000e+00 3.330669073875e-18 1.500000000000e-02"/>
      <geometry>
        <cylinder length="0.029999999999999999" radius="0.0132"/>
      </geometry>
      <material name="mat__5">
        <color rgba="0 0.7 0 1"/>
      </material>
    </collision>
    <inertial>
      <mass value="0.45663411908479401"/>
      <origin xyz="0.000000000000e+00 4.156409787513e-20 1.158881434989e-02"/>
      <inertia ixx="0.0013744652662453566" ixy="0" ixz="0" iyy="0.00037446526624535631" iyz="3.7374454579009944e-21" izz="0.0017002672368287403"/>
    </inertial>
  </link>
  <link name="BASE_Y_lk">
    <visual>
      <origin rpy="-1.570796326795e+00 -0.000000000000e+00 0.000000000000e+00" xyz="0.000000000000e+00 4.000000000000e-03 7.703719777549e-34"/>
      <geometry>
        <cylinder length="0.0080000000000000002" radius="0.040000000000000001"/>
      </geometry>
      <material name="mat__6">
        <color rgba="0.7 0 0 1"/>
      </material>
    </visual>
    <visual>
      <origin rpy="-3.141592653590e+00 -1.570796326795e+00 0.000000000000e+00" xyz="-2.000000000000e-02 2.500000000000e-02 9.992007221626e-18"/>
      <geometry>
        <cylinder length="0.040000000000000001" radius="0.016"/>
      </geometry>
      <material name="mat__7">
        <color rgba="0.35 0 0 1"/>
      </material>
    </visual>
    <visual>
      <origin rpy="-1.570796326795e+00 -0.000000000000e+00 0.000000000000e+00" xyz="0.000000000000e+00 1.250000000000e-02 -7.703719777549e-34"/>
      <geometry>
        <cylinder length="0.025000000000000001" radius="0.0132"/>
      </geometry>
      <material name="mat__8">
        <color rgba="0 0.7 0 1"/>
      </material>
    </visual>
    <collision>
      <origin rpy="-1.570796326795e+00 -0.000000000000e+00 0.000000000000e+00" xyz="0.000000000000e+00 4.000000000000e-03 7.703719777549e-34"/>
      <geometry>
        <cylinder length="0.0080000000000000002" radius="0.040000000000000001"/>
      </geometry>
      <material name="mat__9">
        <color rgba="0.7 0 0 1"/>
      </material>
    </collision>
    <collision>
      <origin rpy="-3.141592653590e+00 -1.570796326795e+00 0.000000000000e+00" xyz="-2.000000000000e-02 2.500000000000e-02 9.992007221626e-18"/>
      <geometry>
        <cylinder length="0.040000000000000001" radius="0.016"/>
      </geometry>
      <material name="mat__10">
        <color rgba="0.35 0 0 1"/>
      </material>
    </collision>
    <collision>
      <origin rpy="-1.570796326795e+00 -0.000000000000e+00 0.000000000000e+00" xyz="0.000000000000e+00 1.250000000000e-02 -7.703719777549e-34"/>
      <geometry>
        <cylinder length="0.025000000000000001" radius="0.0132"/>
      </geometry>
      <material name="mat__11">
        <color rgba="0 0.7 0 1"/>
      </material>
    </collision>
    <inertial>
      <mass value="0.086067072337745965"/>
      <origin xyz="-7.475543875018e-03 1.320083223828e-02 3.734784419238e-18"/>
      <inertia ixx="2.9615646440363949e-05" ixy="7.5915630097784371e-06" ixz="4.5211444592249744e-21" iyy="4.7768534147727311e-05" iyz="-3.7927476208569014e-21" izz="3.990430566799044e-05"/>
    </inertial>
  </link>
  <joint name="BASE_Y" type="continuous">
    <parent link="arm_base"/>
    <child link="BASE_Y_lk"/>
    <origin rpy="1.570796326795e+00 -0.000000000000e+00 0.000000000000e+00" xyz="0.000000000000e+00 0.000000000000e+00 3.000000000000e-02"/>
    <axis xyz="0.000000000000e+00 1.000000000000e+00 0.000000000000e+00"/>
    <limit effort="1.7976931348623157e+3" lower="-1.7976931348623157e+3" upper="1.7976931348623157e+3" velocity="1.7976931348623157e+3"/>
  </joint>
  <transmission name="BASE_Y_trans">
    <type>transmission_interface/SimpleTransmission</type>
    <joint name="BASE_Y">
      <hardwareInterface>hardware_interface/EffortJointInterface</hardwareInterface>
    </joint>
    <actuator name="BASE_Y_motor">
      <hardwareInterface>hardware_interface/EffortJointInterface</hardwareInterface>
    </actuator>
  </transmission>
  <link name="BASE_R_lk">
    <visual>
      <origin rpy="-1.570796326795e+00 -0.000000000000e+00 0.000000000000e+00" xyz="0.000000000000e+00 2.000000000000e-02 0.000000000000e+00"/>
      <geometry>
        <cylinder length="0.040000000000000001" radius="0.016"/>
      </geometry>
      <material name="mat__12">
        <color rgba="0.7 0 0 1"/>
      </material>
    </visual>
    <visual>
      <origin rpy="-1.570796326795e+00 -0.000000000000e+00 1.570796326795e+00" xyz="2.000000000000e-02 -4.440892098501e-18 0.000000000000e+00"/>
      <geometry>
        <cylinder length="0.040000000000000001" radius="0.016"/>
      </geometry>
      <material name="mat__13">
        <color rgba="0.35 0 0 1"/>
      </material>
    </visual>
    <collision>
      <origin rpy="-1.570796326795e+00 -0.000000000000e+00 0.000000000000e+00" xyz="0.000000000000e+00 2.000000000000e-02 0.000000000000e+00"/>
      <geometry>
        <cylinder length="0.040000000000000001" radius="0.016"/>
      </geometry>
      <material name="mat__14">
        <color rgba="0.7 0 0 1"/>
      </material>
    </collision>
    <collision>
      <origin rpy="-1.570796326795e+00 -0.000000000000e+00 1.570796326795e+00" xyz="2.000000000000e-02 -4.440892098501e-18 0.000000000000e+00"/>
      <geometry>
        <cylinder length="0.040000000000000001" radius="0.016"/>
      </geometry>
      <material name="mat__15">
        <color rgba="0.35 0 0 1"/>
      </material>
    </collision>
    <inertial>
      <mass value="0.064339817545518957"/>
      <origin xyz="1.000000000000e-02 1.000000000000e-02 0.000000000000e+00"/>
      <inertia ixx="1.6899925408622984e-05" ixy="6.433981754551899e-06" ixz="0" iyy="1.689992540862298e-05" iyz="0" izz="2.5564354171419536e-05"/>
    </inertial>
  </link>
  <joint name="BASE_R" type="continuous">
    <parent link="BASE_Y_lk"/>
    <child link="BASE_R_lk"/>
    <origin rpy="-1.570796326795e+00 -1.570796326795e+00 0.000000000000e+00" xyz="0.000000000000e+00 2.500000000000e-02 5.551115123126e-18"/>
    <axis xyz="0.000000000000e+00 1.000000000000e+00 0.000000000000e+00"/>
    <limit effort="1.7976931348623157e+3" lower="-1.7976931348623157e+3" upper="1.7976931348623157e+3" velocity="1.7976931348623157e+3"/>
  </joint>
  <transmission name="BASE_R_trans">
    <type>transmission_interface/SimpleTransmission</type>
    <joint name="BASE_R">
      <hardwareInterface>hardware_interface/EffortJointInterface</hardwareInterface>
    </joint>
    <actuator name="BASE_R_motor">
      <hardwareInterface>hardware_interface/EffortJointInterface</hardwareInterface>
    </actuator>
  </transmission>
  <link name="BASE_P_lk">
    <visual>
      <origin rpy="-1.570796326795e+00 -0.000000000000e+00 0.000000000000e+00" xyz="0.000000000000e+00 2.000000000000e-02 0.000000000000e+00"/>
      <geometry>
        <cylinder length="0.040000000000000001" radius="0.016"/>
      </geometry>
      <material name="mat__16">
        <color rgba="0.7 0 0 1"/>
      </material>
    </visual>
    <visual>
      <origin rpy="-1.570796326795e+00 -0.000000000000e+00 0.000000000000e+00" xyz="0.000000000000e+00 -2.000000000000e-02 2.500000000000e-01"/>
      <geometry>
        <cylinder length="0.040000000000000001" radius="0.016"/>
      </geometry>
      <material name="mat__17">
        <color rgba="0.35 0 0 1"/>
      </material>
    </visual>
    <visual>
      <origin rpy="-1.608122649677e-16 -0.000000000000e+00 0.000000000000e+00" xyz="0.000000000000e+00 2.775557561563e-17 1.250000000000e-01"/>
      <geometry>
        <cylinder length="0.25" radius="0.0132"/>
      </geometry>
      <material name="mat__18">
        <color rgba="0 0.7 0 1"/>
      </material>
    </visual>
    <collision>
      <origin rpy="-1.570796326795e+00 -0.000000000000e+00 0.000000000000e+00" xyz="0.000000000000e+00 2.000000000000e-02 0.000000000000e+00"/>
      <geometry>
        <cylinder length="0.040000000000000001" radius="0.016"/>
      </geometry>
      <material name="mat__19">
        <color rgba="0.7 0 0 1"/>
      </material>
    </collision>
    <collision>
      <origin rpy="-1.570796326795e+00 -0.000000000000e+00 0.000000000000e+00" xyz="0.000000000000e+00 -2.000000000000e-02 2.500000000000e-01"/>
      <geometry>
        <cylinder length="0.040000000000000001" radius="0.016"/>
      </geometry>
      <material name="mat__20">
        <color rgba="0.35 0 0 1"/>
      </material>
    </collision>
    <collision>
      <origin rpy="-1.608122649677e-16 -0.000000000000e+00 0.000000000000e+00" xyz="0.000000000000e+00 2.775557561563e-17 1.250000000000e-01"/>
      <geometry>
        <cylinder length="0.25" radius="0.0132"/>
      </geometry>
      <material name="mat__21">
        <color rgba="0 0.7 0 1"/>
      </material>
    </collision>
    <inertial>
      <mass value="0.20118759353589033"/>
      <origin xyz="0.000000000000e+00 1.887933906647e-17 1.250000000000e-01"/>
      <inertia ixx="0.001762451889234582" ixy="0" ixz="0" iyy="0.0017322550681998848" iyz="0.00016084954386379722" izz="5.0354495924804477e-05"/>
    </inertial>
  </link>
  <joint name="BASE_P" type="continuous">
    <parent link="BASE_R_lk"/>
    <child link="BASE_P_lk"/>
    <origin rpy="2.465190328816e-32 2.465190328816e-32 1.570796326795e+00" xyz="0.000000000000e+00 0.000000000000e+00 0.000000000000e+00"/>
    <axis xyz="0.000000000000e+00 1.000000000000e+00 0.000000000000e+00"/>
    <limit effort="1.7976931348623157e+3" lower="-1.7976931348623157e+3" upper="1.7976931348623157e+3" velocity="1.7976931348623157e+3"/>
  </joint>
  <transmission name="BASE_P_trans">
    <type>transmission_interface/SimpleTransmission</type>
    <joint name="BASE_P">
      <hardwareInterface>hardware_interface/EffortJointInterface</hardwareInterface>
    </joint>
    <actuator name="BASE_P_motor">
      <hardwareInterface>hardware_interface/EffortJointInterface</hardwareInterface>
    </actuator>
  </transmission>
  <link name="ELBOW_P_lk">
    <visual>
      <origin rpy="-1.570796326795e+00 -0.000000000000e+00 0.000000000000e+00" xyz="0.000000000000e+00 2.000000000000e-02 0.000000000000e+00"/>
      <geometry>
        <cylinder length="0.040000000000000001" radius="0.016"/>
      </geometry>
      <material name="mat__22">
        <color rgba="0.7 0 0 1"/>
      </material>
    </visual>
    <visual>
      <origin rpy="-1.608122649677e-16 -0.000000000000e+00 0.000000000000e+00" xyz="0.000000000000e+00 -8.881784197001e-19 2.100000000000e-02"/>
      <geometry>
        <cylinder length="0.0080000000000000002" radius="0.040000000000000001"/>
      </geometry>
      <material name="mat__23">
        <color rgba="0.35 0 0 1"/>
      </material>
    </visual>
    <visual>
      <origin rpy="-1.608122649677e-16 -0.000000000000e+00 0.000000000000e+00" xyz="0.000000000000e+00 2.775557561563e-18 1.250000000000e-02"/>
      <geometry>
        <cylinder length="0.025000000000000022" radius="0.0132"/>
      </geometry>
      <material name="mat__24">
        <color rgba="0 0.7 0 1"/>
      </material>
    </visual>
    <collision>
      <origin rpy="-1.570796326795e+00 -0.000000000000e+00 0.000000000000e+00" xyz="0.000000000000e+00 2.000000000000e-02 0.000000000000e+00"/>
      <geometry>
        <cylinder length="0.040000000000000001" radius="0.016"/>
      </geometry>
      <material name="mat__25">
        <color rgba="0.7 0 0 1"/>
      </material>
    </collision>
    <collision>
      <origin rpy="-1.608122649677e-16 -0.000000000000e+00 0.000000000000e+00" xyz="0.000000000000e+00 -8.881784197001e-19 2.100000000000e-02"/>
      <geometry>
        <cylinder length="0.0080000000000000002" radius="0.040000000000000001"/>
      </geometry>
      <material name="mat__26">
        <color rgba="0.35 0 0 1"/>
      </material>
    </collision>
    <collision>
      <origin rpy="-1.608122649677e-16 -0.000000000000e+00 0.000000000000e+00" xyz="0.000000000000e+00 2.775557561563e-18 1.250000000000e-02"/>
      <geometry>
        <cylinder length="0.025000000000000022" radius="0.0132"/>
      </geometry>
      <material name="mat__27">
        <color rgba="0 0.7 0 1"/>
      </material>
    </collision>
    <inertial>
      <mass value="0.086067072337745978"/>
      <origin xyz="0.000000000000e+00 7.475543875018e-03 1.179916776172e-02"/>
      <inertia ixx="3.9904305667990454e-05" ixy="0" ixz="0" iyy="2.9615646440363966e-05" iyz="7.5915630097784473e-06" izz="4.7768534147727311e-05"/>
    </inertial>
  </link>
  <joint name="ELBOW_P" type="continuous">
    <parent link="BASE_P_lk"/>
    <child link="ELBOW_P_lk"/>
    <origin rpy="-2.465190328816e-32 4.930380657631e-32 -6.077163357286e-64" xyz="-1.848892746612e-32 6.162975822039e-33 2.500000000000e-01"/>
    <axis xyz="0.000000000000e+00 1.000000000000e+00 0.000000000000e+00"/>
    <limit effort="1.7976931348623157e+3" lower="-1.7976931348623157e+3" upper="1.7976931348623157e+3" velocity="1.7976931348623157e+3"/>
  </joint>
  <transmission name="ELBOW_P_trans">
    <type>transmission_interface/SimpleTransmission</type>
    <joint name="ELBOW_P">
      <hardwareInterface>hardware_interface/EffortJointInterface</hardwareInterface>
    </joint>
    <actuator name="ELBOW_P_motor">
      <hardwareInterface>hardware_interface/EffortJointInterface</hardwareInterface>
    </actuator>
  </transmission>
  <link name="ELBOW_Y_lk">
    <visual>
      <origin rpy="-1.570796326795e+00 -0.000000000000e+00 0.000000000000e+00" xyz="0.000000000000e+00 4.000000000000e-03 0.000000000000e+00"/>
      <geometry>
        <cylinder length="0.0080000000000000002" radius="0.040000000000000001"/>
      </geometry>
      <material name="mat__28">
        <color rgba="0.7 0 0 1"/>
      </material>
    </visual>
    <visual>
      <origin rpy="-3.141592653590e+00 -0.000000000000e+00 0.000000000000e+00" xyz="0.000000000000e+00 2.250000000000e-01 2.000000000000e-02"/>
      <geometry>
        <cylinder length="0.040000000000000001" radius="0.016"/>
      </geometry>
      <material name="mat__29">
        <color rgba="0.35 0 0 1"/>
      </material>
    </visual>
    <visual>
      <origin rpy="-1.570796326795e+00 -0.000000000000e+00 0.000000000000e+00" xyz="0.000000000000e+00 1.125000000000e-01 -1.232595164408e-32"/>
      <geometry>
        <cylinder length="0.22500000000000003" radius="0.0132"/>
      </geometry>
      <material name="mat__30">
        <color rgba="0 0.7 0 1"/>
      </material>
    </visual>
    <collision>
      <origin rpy="-1.570796326795e+00 -0.000000000000e+00 0.000000000000e+00" xyz="0.000000000000e+00 4.000000000000e-03 0.000000000000e+00"/>
      <geometry>
        <cylinder length="0.0080000000000000002" radius="0.040000000000000001"/>
      </geometry>
      <material name="mat__31">
        <color rgba="0.7 0 0 1"/>
      </material>
    </collision>
    <collision>
      <origin rpy="-3.141592653590e+00 -0.000000000000e+00 0.000000000000e+00" xyz="0.000000000000e+00 2.250000000000e-01 2.000000000000e-02"/>
      <geometry>
        <cylinder length="0.040000000000000001" radius="0.016"/>
      </geometry>
      <material name="mat__32">
        <color rgba="0.35 0 0 1"/>
      </material>
    </collision>
    <collision>
      <origin rpy="-1.570796326795e+00 -0.000000000000e+00 0.000000000000e+00" xyz="0.000000000000e+00 1.125000000000e-01 -1.232595164408e-32"/>
      <geometry>
        <cylinder length="0.22500000000000003" radius="0.0132"/>
      </geometry>
      <material name="mat__33">
        <color rgba="0 0.7 0 1"/>
      </material>
    </collision>
    <inertial>
      <mass value="0.1955452931300431"/>
      <origin xyz="0.000000000000e+00 1.086956172482e-01 3.290276974488e-03"/>
      <inertia ixx="0.0014360679781591028" ixy="0" ixz="0" iyy="5.9999069830746762e-05" iyz="-7.4830027659918938e-05" izz="0.0014230865258438817"/>
    </inertial>
  </link>
  <joint name="ELBOW_Y" type="continuous">
    <parent link="ELBOW_P_lk"/>
    <child link="ELBOW_Y_lk"/>
    <origin rpy="1.570796326795e+00 4.930380657631e-32 9.115745035929e-64" xyz="1.047705889747e-32 1.642146637881e-48 2.500000000000e-02"/>
    <axis xyz="0.000000000000e+00 1.000000000000e+00 0.000000000000e+00"/>
    <limit effort="1.7976931348623157e+3" lower="-1.7976931348623157e+3" upper="1.7976931348623157e+3" velocity="1.7976931348623157e+3"/>
  </joint>
  <transmission name="ELBOW_Y_trans">
    <type>transmission_interface/SimpleTransmission</type>
    <joint name="ELBOW_Y">
      <hardwareInterface>hardware_interface/EffortJointInterface</hardwareInterface>
    </joint>
    <actuator name="ELBOW_Y_motor">
      <hardwareInterface>hardware_interface/EffortJointInterface</hardwareInterface>
    </actuator>
  </transmission>
  <link name="WRIST_P_lk">
    <visual>
      <origin rpy="-1.570796326795e+00 -0.000000000000e+00 0.000000000000e+00" xyz="0.000000000000e+00 2.000000000000e-02 0.000000000000e+00"/>
      <geometry>
        <cylinder length="0.040000000000000001" radius="0.016"/>
      </geometry>
      <material name="mat__34">
        <color rgba="0.7 0 0 1"/>
      </material>
    </visual>
    <visual>
      <origin rpy="-1.608122649677e-16 -0.000000000000e+00 0.000000000000e+00" xyz="0.000000000000e+00 -8.881784197001e-19 2.100000000000e-02"/>
      <geometry>
        <cylinder length="0.0080000000000000002" radius="0.040000000000000001"/>
      </geometry>
      <material name="mat__35">
        <color rgba="0.35 0 0 1"/>
      </material>
    </visual>
    <visual>
      <origin rpy="-1.608122649677e-16 -0.000000000000e+00 0.000000000000e+00" xyz="0.000000000000e+00 2.775557561563e-18 1.250000000000e-02"/>
      <geometry>
        <cylinder length="0.025000000000000022" radius="0.0132"/>
      </geometry>
      <material name="mat__36">
        <color rgba="0 0.7 0 1"/>
      </material>
    </visual>
    <collision>
      <origin rpy="-1.570796326795e+00 -0.000000000000e+00 0.000000000000e+00" xyz="0.000000000000e+00 2.000000000000e-02 0.000000000000e+00"/>
      <geometry>
        <cylinder length="0.040000000000000001" radius="0.016"/>
      </geometry>
      <material name="mat__37">
        <color rgba="0.7 0 0 1"/>
      </material>
    </collision>
    <collision>
      <origin rpy="-1.608122649677e-16 -0.000000000000e+00 0.000000000000e+00" xyz="0.000000000000e+00 -8.881784197001e-19 2.100000000000e-02"/>
      <geometry>
        <cylinder length="0.0080000000000000002" radius="0.040000000000000001"/>
      </geometry>
      <material name="mat__38">
        <color rgba="0.35 0 0 1"/>
      </material>
    </collision>
    <collision>
      <origin rpy="-1.608122649677e-16 -0.000000000000e+00 0.000000000000e+00" xyz="0.000000000000e+00 2.775557561563e-18 1.250000000000e-02"/>
      <geometry>
        <cylinder length="0.025000000000000022" radius="0.0132"/>
      </geometry>
      <material name="mat__39">
        <color rgba="0 0.7 0 1"/>
      </material>
    </collision>
    <inertial>
      <mass value="0.086067072337745978"/>
      <origin xyz="0.000000000000e+00 7.475543875018e-03 1.179916776172e-02"/>
      <inertia ixx="3.9904305667990461e-05" ixy="0" ixz="0" iyy="2.961564644036397e-05" iyz="7.5915630097784523e-06" izz="4.7768534147727311e-05"/>
    </inertial>
  </link>
  <joint name="WRIST_P" type="continuous">
    <parent link="ELBOW_Y_lk"/>
    <child link="WRIST_P_lk"/>
    <origin rpy="-1.570796326795e+00 -2.465190328816e-32 -4.930380657631e-32" xyz="-1.540743955510e-32 2.250000000000e-01 4.996003610813e-17"/>
    <axis xyz="0.000000000000e+00 1.000000000000e+00 0.000000000000e+00"/>
    <limit effort="1.7976931348623157e+3" lower="-1.7976931348623157e+3" upper="1.7976931348623157e+3" velocity="1.7976931348623157e+3"/>
  </joint>
  <transmission name="WRIST_P_trans">
    <type>transmission_interface/SimpleTransmission</type>
    <joint name="WRIST_P">
      <hardwareInterface>hardware_interface/EffortJointInterface</hardwareInterface>
    </joint>
    <actuator name="WRIST_P_motor">
      <hardwareInterface>hardware_interface/EffortJointInterface</hardwareInterface>
    </actuator>
  </transmission>
  <link name="WRIST_Y_lk">
    <visual>
      <origin rpy="-1.570796326795e+00 -0.000000000000e+00 0.000000000000e+00" xyz="0.000000000000e+00 4.000000000000e-03 0.000000000000e+00"/>
      <geometry>
        <cylinder length="0.0080000000000000002" radius="0.040000000000000001"/>
      </geometry>
      <material name="mat__40">
        <color rgba="0.7 0 0 1"/>
      </material>
    </visual>
    <visual>
      <origin rpy="-3.141592653590e+00 -1.570796326795e+00 0.000000000000e+00" xyz="-2.000000000000e-02 2.500000000000e-02 9.992007221626e-18"/>
      <geometry>
        <cylinder length="0.040000000000000001" radius="0.016"/>
      </geometry>
      <material name="mat__41">
        <color rgba="0.35 0 0 1"/>
      </material>
    </visual>
    <visual>
      <origin rpy="-3.141592653590e+00 -1.570796326795e+00 0.000000000000e+00" xyz="-2.000000000000e-02 2.500000000000e-02 9.992007221626e-18"/>
      <geometry>
        <cylinder length="0.040000000000000001" radius="0.016"/>
      </geometry>
      <material name="mat__42">
        <color rgba="0.35 0 0 1"/>
      </material>
    </visual>
    <visual>
      <origin rpy="-1.570796326795e+00 -0.000000000000e+00 0.000000000000e+00" xyz="0.000000000000e+00 1.250000000000e-02 0.000000000000e+00"/>
      <geometry>
        <cylinder length="0.025000000000000022" radius="0.0132"/>
      </geometry>
      <material name="mat__43">
        <color rgba="0 0.7 0 1"/>
      </material>
    </visual>
    <visual>
      <origin rpy="-1.570796326795e+00 -0.000000000000e+00 0.000000000000e+00" xyz="0.000000000000e+00 1.250000000000e-02 0.000000000000e+00"/>
      <geometry>
        <cylinder length="0.025000000000000022" radius="0.0132"/>
      </geometry>
      <material name="mat__44">
        <color rgba="0 0.7 0 1"/>
      </material>
    </visual>
    <collision>
      <origin rpy="-1.570796326795e+00 -0.000000000000e+00 0.000000000000e+00" xyz="0.000000000000e+00 4.000000000000e-03 0.000000000000e+00"/>
      <geometry>
        <cylinder length="0.0080000000000000002" radius="0.040000000000000001"/>
      </geometry>
      <material name="mat__45">
        <color rgba="0.7 0 0 1"/>
      </material>
    </collision>
    <collision>
      <origin rpy="-3.141592653590e+00 -1.570796326795e+00 0.000000000000e+00" xyz="-2.000000000000e-02 2.500000000000e-02 9.992007221626e-18"/>
      <geometry>
        <cylinder length="0.040000000000000001" radius="0.016"/>
      </geometry>
      <material name="mat__46">
        <color rgba="0.35 0 0 1"/>
      </material>
    </collision>
    <collision>
      <origin rpy="-3.141592653590e+00 -1.570796326795e+00 0.000000000000e+00" xyz="-2.000000000000e-02 2.500000000000e-02 9.992007221626e-18"/>
      <geometry>
        <cylinder length="0.040000000000000001" radius="0.016"/>
      </geometry>
      <material name="mat__47">
        <color rgba="0.35 0 0 1"/>
      </material>
    </collision>
    <collision>
      <origin rpy="-1.570796326795e+00 -0.000000000000e+00 0.000000000000e+00" xyz="0.000000000000e+00 1.250000000000e-02 0.000000000000e+00"/>
      <geometry>
        <cylinder length="0.025000000000000022" radius="0.0132"/>
      </geometry>
      <material name="mat__48">
        <color rgba="0 0.7 0 1"/>
      </material>
    </collision>
    <collision>
      <origin rpy="-1.570796326795e+00 -0.000000000000e+00 0.000000000000e+00" xyz="0.000000000000e+00 1.250000000000e-02 0.000000000000e+00"/>
      <geometry>
        <cylinder length="0.025000000000000022" radius="0.0132"/>
      </geometry>
      <material name="mat__49">
        <color rgba="0 0.7 0 1"/>
      </material>
    </collision>
    <inertial>
      <mass value="0.13192175870954262"/>
      <origin xyz="-9.754238902648e-03 1.600542960564e-02 4.873221277836e-18"/>
      <inertia ixx="3.8490014544011007e-05" ixy="1.1574180361470074e-05" ixz="7.577352523064054e-21" iyy="6.0434943076303381e-05" iyz="-5.782464687810782e-21" izz="5.6135116552872243e-05"/>
    </inertial>
  </link>
  <joint name="WRIST_Y" type="continuous">
    <parent link="WRIST_P_lk"/>
    <child link="WRIST_Y_lk"/>
    <origin rpy="1.570796326795e+00 4.930380657631e-32 2.465190328816e-32" xyz="9.244463733059e-33 2.736911063134e-49 2.500000000000e-02"/>
    <axis xyz="0.000000000000e+00 1.000000000000e+00 0.000000000000e+00"/>
    <limit effort="1.7976931348623157e+3" lower="-1.7976931348623157e+3" upper="1.7976931348623157e+3" velocity="1.7976931348623157e+3"/>
  </joint>
  <transmission name="WRIST_Y_trans">
    <type>transmission_interface/SimpleTransmission</type>
    <joint name="WRIST_Y">
      <hardwareInterface>hardware_interface/EffortJointInterface</hardwareInterface>
    </joint>
    <actuator name="WRIST_Y_motor">
      <hardwareInterface>hardware_interface/EffortJointInterface</hardwareInterface>
    </actuator>
  </transmission>
  <link name="GRIPPER0_lk">
    <visual>
      <origin rpy="-1.570796326795e+00 -0.000000000000e+00 0.000000000000e+00" xyz="0.000000000000e+00 2.000000000000e-02 0.000000000000e+00"/>
      <geometry>
        <cylinder length="0.040000000000000001" radius="0.016"/>
      </geometry>
      <material name="mat__50">
        <color rgba="0.7 0 0 1"/>
      </material>
    </visual>
    <visual>
      <geometry>
        <mesh filename="package://irsl_mobile_arm/model/BodyBuilder_GRIPPER0_lk.dae"/>
      </geometry>
    </visual>
    <collision>
      <origin rpy="-1.570796326795e+00 -0.000000000000e+00 0.000000000000e+00" xyz="0.000000000000e+00 2.000000000000e-02 0.000000000000e+00"/>
      <geometry>
        <cylinder length="0.040000000000000001" radius="0.016"/>
      </geometry>
      <material name="mat__51">
        <color rgba="0.7 0 0 1"/>
      </material>
    </collision>
    <collision>
      <geometry>
        <mesh filename="package://irsl_mobile_arm/model/BodyBuilder_GRIPPER0_lk.stl"/>
      </geometry>
    </collision>
    <inertial>
      <mass value="0.21978987015193907"/>
      <origin xyz="-1.964929816291e-02 2.927333239006e-03 7.575149021598e-02"/>
      <inertia ixx="0.00083441482670501815" ixy="-1.2642322577907088e-05" ixz="-1.6655085154564249e-05" iyy="0.00079797034509641396" iyz="4.8738369652698547e-05" izz="0.0001473261756837552"/>
    </inertial>
  </link>
  <joint name="GRIPPER0" type="continuous">
    <parent link="WRIST_Y_lk"/>
    <child link="GRIPPER0_lk"/>
    <origin rpy="-1.570796326795e+00 -1.570796326795e+00 0.000000000000e+00" xyz="-6.162975822039e-34 2.500000000000e-02 5.551115123126e-18"/>
    <axis xyz="0.000000000000e+00 1.000000000000e+00 0.000000000000e+00"/>
    <limit effort="1.7976931348623157e+3" lower="-1.7976931348623157e+3" upper="1.7976931348623157e+3" velocity="1.7976931348623157e+3"/>
  </joint>
  <transmission name="GRIPPER0_trans">
    <type>transmission_interface/SimpleTransmission</type>
    <joint name="GRIPPER0">
      <hardwareInterface>hardware_interface/EffortJointInterface</hardwareInterface>
    </joint>
    <actuator name="GRIPPER0_motor">
      <hardwareInterface>hardware_interface/EffortJointInterface</hardwareInterface>
    </actuator>
  </transmission>
  <link name="GRIPPER1_lk">
    <visual>
      <origin rpy="-1.570796326795e+00 -0.000000000000e+00 0.000000000000e+00" xyz="0.000000000000e+00 2.000000000000e-02 0.000000000000e+00"/>
      <geometry>
        <cylinder length="0.040000000000000001" radius="0.016"/>
      </geometry>
      <material name="mat__52">
        <color rgba="0.7 0 0 1"/>
      </material>
    </visual>
    <visual>
      <geometry>
        <mesh filename="package://irsl_mobile_arm/model/BodyBuilder_GRIPPER1_lk.dae"/>
      </geometry>
    </visual>
    <collision>
      <origin rpy="-1.570796326795e+00 -0.000000000000e+00 0.000000000000e+00" xyz="0.000000000000e+00 2.000000000000e-02 0.000000000000e+00"/>
      <geometry>
        <cylinder length="0.040000000000000001" radius="0.016"/>
      </geometry>
      <material name="mat__53">
        <color rgba="0.7 0 0 1"/>
      </material>
    </collision>
    <collision>
      <geometry>
        <mesh filename="package://irsl_mobile_arm/model/BodyBuilder_GRIPPER1_lk.stl"/>
      </geometry>
    </collision>
    <inertial>
      <mass value="0.21978987015193907"/>
      <origin xyz="1.964929816291e-02 2.927333239006e-03 7.575149021598e-02"/>
      <inertia ixx="0.00083441482670501815" ixy="1.2642322577907061e-05" ixz="1.6655085154564277e-05" iyy="0.00079797034509641396" iyz="4.8738369652698506e-05" izz="0.00014732617568375517"/>
    </inertial>
  </link>
  <joint name="GRIPPER1" type="continuous">
    <parent link="WRIST_Y_lk"/>
    <child link="GRIPPER1_lk"/>
    <origin rpy="-1.570796326795e+00 -1.570796326795e+00 0.000000000000e+00" xyz="-6.162975822039e-34 2.500000000000e-02 5.551115123126e-18"/>
    <axis xyz="0.000000000000e+00 1.000000000000e+00 0.000000000000e+00"/>
    <limit effort="1.7976931348623157e+3" lower="-1.7976931348623157e+3" upper="1.7976931348623157e+3" velocity="1.7976931348623157e+3"/>
  </joint>
  <transmission name="GRIPPER1_trans">
    <type>transmission_interface/SimpleTransmission</type>
    <joint name="GRIPPER1">
      <hardwareInterface>hardware_interface/EffortJointInterface</hardwareInterface>
    </joint>
    <actuator name="GRIPPER1_motor">
      <hardwareInterface>hardware_interface/EffortJointInterface</hardwareInterface>
    </actuator>
  </transmission>
  <joint name="connect_arm" type="fixed">
    <parent link="anchor_arm_base"/>
    <child link="arm_base"/>
  </joint>
  <gazebo>
    <plugin filename="libgazebo_ros_control.so" name="gazebo_ros_control">
      <robotNamespace>/</robotNamespace>
    </plugin>
  </gazebo>
  <link name="base_camera_link"/>
  <joint name="fixed_main_to_base_camera_link" type="fixed">
    <parent link="main"/>
    <child link="base_camera_link"/>
    <origin rpy="0 0 0" xyz="0.2 0.0 0.15"/>
  </joint>
  <link name="arm_camera_link"/>
  <joint name="fixed_main_to_arm_camera_link" type="fixed">
    <parent link="ELBOW_Y_lk"/>
    <child link="arm_camera_link"/>
    <origin rpy="-1.5707963267948966 0 1.5707963267948966" xyz="-0.1 0.12 0"/>
  </joint>
  <link name="hand_camera_link"/>
  <joint name="fixed_main_to_hand_camera_link" type="fixed">
    <parent link="WRIST_Y_lk"/>
    <child link="hand_camera_link"/>
    <origin rpy="-1.5707963267948966 0 1.5707963267948966" xyz="-0.07 0.025 0"/>
  </joint>
  <!-- create camera frame-->
  <link name="base_camera_frame"/>
  <joint name="base_camera_frame_fixed_joint" type="fixed">
    <parent link="base_camera_link"/>
    <child link="base_camera_frame"/>
    <origin rpy="-1.5707963267948966 0 -1.5707963267948966" xyz="0 0 0"/>
  </joint>
  <!-- camera -->
  <gazebo reference="base_camera_link">
    <sensor name="base_camera_link_camera" type="camera">
      <pose>0 0 0 0 0 0</pose>
      <always_on>true</always_on>
      <update_rate>30.0</update_rate>
      <visualize>True</visualize>
      <camera name="base_camera_link_camera">
        <horizontal_fov>1.578</horizontal_fov>
        <image>
          <width>800</width>
          <height>600</height>
          <format>B8G8R8</format>
        </image>
        <clip>
          <near>0.02</near>
          <far>300</far>
        </clip>
        <noise>
          <type>gaussian</type>
          <!-- Noise is sampled independently per pixel on each frame.
                 That pixel's noise value is added to each of its color
                 channels, which at that point lie in the range [0,1]. -->
          <mean>0.0</mean>
          <stddev>0.007</stddev>
        </noise>
      </camera>
      <plugin filename="libgazebo_ros_camera.so" name="camera_controller">
        <alwaysOn>true</alwaysOn>
        <updateRate>0.0</updateRate>
        <!-- ? -->
        <cameraName>base_camera</cameraName>
        <imageTopicName>image_raw</imageTopicName>
        <cameraInfoTopicName>camera_info</cameraInfoTopicName>
        <frameName>base_camera_frame</frameName>
        <hackBaseline>0.07</hackBaseline>
        <distortionK1>0.0</distortionK1>
        <distortionK2>0.0</distortionK2>
        <distortionK3>0.0</distortionK3>
        <distortionT1>0.0</distortionT1>
        <distortionT2>0.0</distortionT2>
      </plugin>
    </sensor>
  </gazebo>
  <!-- create camera frame-->
  <link name="arm_camera_frame"/>
  <joint name="arm_camera_frame_fixed_joint" type="fixed">
    <parent link="arm_camera_link"/>
    <child link="arm_camera_frame"/>
    <origin rpy="-1.5707963267948966 0 -1.5707963267948966" xyz="0 0 0"/>
  </joint>
  <!-- camera -->
  <gazebo reference="arm_camera_link">
    <sensor name="arm_camera_link_camera" type="camera">
      <pose>0 0 0 0 0 0</pose>
      <always_on>true</always_on>
      <update_rate>30.0</update_rate>
      <visualize>True</visualize>
      <camera name="arm_camera_link_camera">
        <horizontal_fov>1.578</horizontal_fov>
        <image>
          <width>800</width>
          <height>600</height>
          <format>B8G8R8</format>
        </image>
        <clip>
          <near>0.02</near>
          <far>300</far>
        </clip>
        <noise>
          <type>gaussian</type>
          <!-- Noise is sampled independently per pixel on each frame.
                 That pixel's noise value is added to each of its color
                 channels, which at that point lie in the range [0,1]. -->
          <mean>0.0</mean>
          <stddev>0.007</stddev>
        </noise>
      </camera>
      <plugin filename="libgazebo_ros_camera.so" name="camera_controller">
        <alwaysOn>true</alwaysOn>
        <updateRate>0.0</updateRate>
        <!-- ? -->
        <cameraName>arm_camera</cameraName>
        <imageTopicName>image_raw</imageTopicName>
        <cameraInfoTopicName>camera_info</cameraInfoTopicName>
        <frameName>arm_camera_frame</frameName>
        <hackBaseline>0.07</hackBaseline>
        <distortionK1>0.0</distortionK1>
        <distortionK2>0.0</distortionK2>
        <distortionK3>0.0</distortionK3>
        <distortionT1>0.0</distortionT1>
        <distortionT2>0.0</distortionT2>
      </plugin>
    </sensor>
  </gazebo>
  <!-- create camera frame-->
  <link name="hand_camera_frame"/>
  <joint name="hand_camera_frame_fixed_joint" type="fixed">
    <parent link="hand_camera_link"/>
    <child link="hand_camera_frame"/>
    <origin rpy="-1.5707963267948966 0 -1.5707963267948966" xyz="0 0 0"/>
  </joint>
  <!-- camera -->
  <gazebo reference="hand_camera_link">
    <sensor name="hand_camera_link_camera" type="camera">
      <pose>0 0 0 0 0 0</pose>
      <always_on>true</always_on>
      <update_rate>30.0</update_rate>
      <visualize>True</visualize>
      <camera name="hand_camera_link_camera">
        <horizontal_fov>1.578</horizontal_fov>
        <image>
          <width>800</width>
          <height>600</height>
          <format>B8G8R8</format>
        </image>
        <clip>
          <near>0.02</near>
          <far>300</far>
        </clip>
        <noise>
          <type>gaussian</type>
          <!-- Noise is sampled independently per pixel on each frame.
                 That pixel's noise value is added to each of its color
                 channels, which at that point lie in the range [0,1]. -->
          <mean>0.0</mean>
          <stddev>0.007</stddev>
        </noise>
      </camera>
      <plugin filename="libgazebo_ros_camera.so" name="camera_controller">
        <alwaysOn>true</alwaysOn>
        <updateRate>0.0</updateRate>
        <!-- ? -->
        <cameraName>hand_camera</cameraName>
        <imageTopicName>image_raw</imageTopicName>
        <cameraInfoTopicName>camera_info</cameraInfoTopicName>
        <frameName>hand_camera_frame</frameName>
        <hackBaseline>0.07</hackBaseline>
        <distortionK1>0.0</distortionK1>
        <distortionK2>0.0</distortionK2>
        <distortionK3>0.0</distortionK3>
        <distortionT1>0.0</distortionT1>
        <distortionT2>0.0</distortionT2>
      </plugin>
    </sensor>
  </gazebo>
</robot>

